Workbook

Sheet Index
A1: Products and Inventory Data
A2: Beitak Smart - Odoo implementation | Entity data (GAWF). Fictional project data; assumptions on the last rows.
A4: Sheet | B4: Content | C4: Instructor requirement
A5: Units of Measure | B5: Units used | C5: Units of Measures
A6: Product Categories | B6: Categories with costing, valuation, accounts | C6: Entity Data 10 / Inventory Evaluation / Cost Methods
A7: Products | B7: 89 products with prices, costs, vendors, tracking | C7: Entity Data 11 - Chart of Products
A8: Bills of Materials | B8: Components per manufactured product | C8: Manufacturing
A9: Work Centers | B9: Work centers and hourly cost | C9: Manufacturing
A10: Operations | B10: Routing per BOM | C10: Manufacturing
A11: BOM Cost Summary | B11: Cost roll-up check | C11: Cost Methods of Products
A12: Price Lists | B12: Retail, wholesale, distributors, key accounts | C12: Entity Data 12 - Price Lists
A13: Warehouses | B13: Warehouses, steps, routes | C13: Warehouse, Locations, Routes, Operations
A14: Locations | B14: All internal locations | C14: Warehouse, Locations
A15: Stock by Location | B15: Opening stock by product and location | C15: Entity Data 13 - by Locations
... A19: Serial Numbers | B19: Serial tracking summary | C19: Warranty traceability
A21: Assumptions
A22: Odoo version | B22: Files target Odoo 18/19 field names (type=Goods + is_storable). On Odoo 17 replace 'type'+'is_storable' with 'detailed_type' = product.
A23: Database | B23: Designed for a NEW clean database with the Egypt fiscal localization. Importing into the old database will clash with existing account codes and products.
A24: Exchange rate | B24: USD/EGP = 50.00 on 2027-01-01. Project assumption, not an official CBE rate.
A25: Landed costs | B25: Cost of imported items = FOB price x 50 x 1.10 (about 10% for freight, duties, clearance and insurance). Assumption.
A26: Sales prices | B26: Sales prices are VAT-exclusive. VAT 14% comes from the Egypt localization default taxes.
A27: Costing | B27: AVCO + automated (perpetual) valuation on all stockable categories. Needed for Landed Costs.
A28: Opening stock | B28: Stock is loaded through Physical Inventory with accounting date 2027-01-01. Its counterpart is account 190100 Opening Stock Clearing, which the opening journal entry closes to zero.
A29: Taxes | B29: VAT 14% and withholding tax 1% / 2% / 3% (team decision). Rates, categories and thresholds must be reviewed by a tax specialist before go-live.
A30: Personal data | B30: All names, emails, phones, tax IDs and bank numbers are fictional placeholders (.example domains).

Sheet Units of Measure
A1: Units of Measure
A2: Only standard Odoo units are used, so no UoM import is needed. Purchase UoM = sales UoM.
A4: Unit | B4: Category | C4: Used For
A5: Units | B5: Unit | C5: Appliances, components, kits, services
A6: kg | B6: Weight | C6: Steel and stainless sheets, powder coating, rubber, aluminum fins, solder
A7: m | B7: Length | C7: Copper wire, copper tube

Sheet Product Categories
A1: Chart of Product Categories
A2: Inventory valuation: AVCO + automated. Accounts drive the automatic journal entries of every stock move.
A4: Category | B4: Parent | C4: Costing Method | D4: Valuation | E4: Stock Valuation Acc. | F4: Stock Input Acc. | G4: Stock Output Acc. | H4: Price Difference Acc. | I4: Income Acc. | J4: Expense / COGS Acc. | K4: Team file name
A5: Air Conditioners & Fans | B5: - | C5: AVCO | D5: Automated | E5: 120300 | F5: 120900 | G5: 120901 | H5: 410900 | I5: 510100 | J5: 410100 | K5: Air Conditioners
A6: Cookers & Ovens | B6: - | C6: AVCO | D6: Automated | E6: 120550 | F6: 120900 | G6: 120901 | H6: 410900 | I6: 510100 | J6: 410100 | K6: Cookers & Ovens
A7: Refrigerators & Freezers | B7: - | C7: AVCO | D7: Automated | E7: 120100 | F7: 120900 | G7: 120901 | H7: 410900 | I7: 510100 | J7: 410100 | K7: Refrigerators
A8: Washing Machines & Dishwashers | B8: - | C8: AVCO | D8: Automated | E8: 120200 | F8: 120900 | G8: 120901 | H8: 410900 | I8: 510100 | J8: 410100 | K8: Washing Machines
A9: TVs & Audio | B9: - | C9: AVCO | D9: Automated | E9: 120400 | F9: 120900 | G9: 120901 | H9: 410900 | I9: 510200 | J9: 410200 | K9: TVs & Audio
A10: Small Appliances | B10: - | C10: AVCO | D10: Automated | E10: 120500 | F10: 120900 | G10: 120901 | H10: 410900 | I10: 510300 | J10: 410300 | K10: -
A11: Small Appliances / Kitchen & Home Care | B11: Small Appliances | C11: AVCO | D11: Automated | E11: 120500 | F11: 120900 | G11: 120901 | H11: 410900 | I11: 510300 | J11: 410300 | K11: Small Appliances / Kitchen
A12: Manufactured | B12: - | C12: AVCO | D12: Automated | E12: 120600 | F12: 120900 | G12: 120901 | H12: 410900 | I12: 510400 | J12: 410400 | K12: -
A13: Manufactured / Accessories | B13: Manufactured | C13: AVCO | D13: Automated | E13: 120600 | F13: 120900 | G13: 120901 | H13: 410900 | I13: 510400 | J13: 410400 | K13: Manufactured / Accessories
A14: Manufactured / Components | B14: Manufactured | C14: AVCO | D14: Automated | E14: 120600 | F14: 120900 | G14: 120901 | H14: 410900 | I14: 510400 | J14: 410400 | K14: Manufactured / Components
A15: Manufactured / Electronics | B15: Manufactured | C15: AVCO | D15: Automated | E15: 120600 | F15: 120900 | G15: 120901 | H15: 410900 | I15: 510400 | J15: 410400 | K15: Manufactured / Electronics
... A28: Landed Costs | B28: - | C28: Standard | D28: Manual | E28: - | F28: - | G28: - | H28: - | I28: - | J28: - | K28: (new)

Sheet Products
A1: Chart of Products
A2: Prices VAT-exclusive. Cost of imported items includes ~10% landed costs (assumption). Manufactured cost = BOM components + operations.
A4: Internal Ref | B4: Product | C4: Category | D4: Kind | E4: Type | F4: Track Inventory | G4: Tracking | H4: UoM | I4: Sales Price | J4: Cost | K4: Margin % | L4: Route | M4: Vendor | N4: Vendor Price | O4: Vendor Currency | P4: Lead Time (days) | Q4: POS | R4: Barcode | S4: Opening Qty | T4: Opening Value
A5: BTK-COM-001 | B5: Sharp Refrigerator 18 Cu. Ft. No-Frost Stainless SJ-GV58G-SL | C5: Refrigerators & Freezers | D5: Trading | E5: Goods | F5: Yes | G5: Serial | H5: Units | I5: 33000 | J5: 26400 | K5: =IF(I5>0,(I5-J5)/I5,"-") -> 0.2 | L5: Buy | M5: Egyptian Home Industries Agency | N5: 26400 | O5: EGP | P5: 5 | Q5: Yes | R5: 2000000000015 | S5: 25 | T5: =S5*J5 -> 660000
A6: BTK-COM-002 | B6: LG Refrigerator 20 Cu. Ft. Digital Inverter GN-B5722HLHU | C6: Refrigerators & Freezers | D6: Trading | E6: Goods | F6: Yes | G6: Serial | H6: Units | I6: 42000 | J6: 33600 | K6: =IF(I6>0,(I6-J6)/I6,"-") -> 0.2 | L6: Buy | M6: Delta Distribution for Home Appliances | N6: 33600 | O6: EGP | P6: 5 | Q6: Yes | R6: 2000000000022 | S6: 18 | T6: =S6*J6 -> 604800
A7: BTK-COM-003 | B7: Samsung Refrigerator 22 Cu. Ft. Side-by-Side RS62R5001M9 | C7: Refrigerators & Freezers | D7: Trading | E7: Goods | F7: Yes | G7: Serial | H7: Units | I7: 72000 | J7: 57600 | K7: =IF(I7>0,(I7-J7)/I7,"-") -> 0.2 | L7: Buy | M7: Delta Distribution for Home Appliances | N7: 57600 | O7: EGP | P7: 5 | Q7: Yes | R7: 2000000000039 | S7: 12 | T7: =S7*J7 -> 691200
A8: BTK-COM-004 | B8: Tornado Refrigerator 14 Cu. Ft. No-Frost RF-48T-SL | C8: Refrigerators & Freezers | D8: Trading | E8: Goods | F8: Yes | G8: Serial | H8: Units | I8: 23500 | J8: 18800 | K8: =IF(I8>0,(I8-J8)/I8,"-") -> 0.2 | L8: Buy | M8: Egyptian Home Industries Agency | N8: 18800 | O8: EGP | P8: 5 | Q8: Yes | R8: 2000000000046 | S8: 30 | T8: =S8*J8 -> 564000
A9: BTK-COM-005 | B9: Kiriazi Refrigerator 16 Cu. Ft. Zomoroda No-Frost K330 | C9: Refrigerators & Freezers | D9: Trading | E9: Goods | F9: Yes | G9: Serial | H9: Units | I9: 26500 | J9: 21200 | K9: =IF(I9>0,(I9-J9)/I9,"-") -> 0.2 | L9: Buy | M9: Egyptian Home Industries Agency | N9: 21200 | O9: EGP | P9: 5 | Q9: Yes | R9: 2000000000053 | S9: 20 | T9: =S9*J9 -> 424000
A10: BTK-COM-006 | B10: Toshiba Deep Freezer 5 Drawers No-Frost GF-18H-S | C10: Refrigerators & Freezers | D10: Trading | E10: Goods | F10: Yes | G10: Serial | H10: Units | I10: 22500 | J10: 18000 | K10: =IF(I10>0,(I10-J10)/I10,"-") -> 0.2 | L10: Buy | M10: Egyptian Home Industries Agency | N10: 18000 | O10: EGP | P10: 5 | Q10: Yes | R10: 2000000000060 | S10: 35 | T10: =S10*J10 -> 630000
A11: BTK-COM-007 | B11: Beko Upright Deep Freezer 7 Drawers RFNE260E13S | C11: Refrigerators & Freezers | D11: Trading | E11: Goods | F11: Yes | G11: Serial | H11: Units | I11: 29500 | J11: 23600 | K11: =IF(I11>0,(I11-J11)/I11,"-") -> 0.2 | L11: Buy | M11: Delta Distribution for Home Appliances | N11: 23600 | O11: EGP | P11: 5 | Q11: Yes | R11: 2000000000077 | S11: 15 | T11: =S11*J11 -> 354000
A12: BTK-COM-008 | B12: Kiriazi Deep Freezer 4 Drawers E220 | C12: Refrigerators & Freezers | D12: Trading | E12: Goods | F12: Yes | G12: Serial | H12: Units | I12: 18200 | J12: 14550 | K12: =IF(I12>0,(I12-J12)/I12,"-") -> 0.20054945 | L12: Buy | M12: Egyptian Home Industries Agency | N12: 14550 | O12: EGP | P12: 5 | Q12: Yes | R12: 2000000000084 | S12: 22 | T12: =S12*J12 -> 320100
A13: BTK-COM-009 | B13: LG Front Load Washer 9 Kg Inverter Steam F4R5VGG2E | C13: Washing Machines & Dishwashers | D13: Trading | E13: Goods | F13: Yes | G13: Serial | H13: Units | I13: 30500 | J13: 24400 | K13: =IF(I13>0,(I13-J13)/I13,"-") -> 0.2 | L13: Buy | M13: Delta Distribution for Home Appliances | N13: 24400 | O13: EGP | P13: 5 | Q13: Yes | R13: 2000000000091 | S13: 28 | T13: =S13*J13 -> 683200
A14: BTK-COM-010 | B14: Samsung Washing Machine 8 Kg Inverter Steam WW80TA046AX | C14: Washing Machines & Dishwashers | D14: Trading | E14: Goods | F14: Yes | G14: Serial | H14: Units | I14: 27000 | J14: 21600 | K14: =IF(I14>0,(I14-J14)/I14,"-") -> 0.2 | L14: Buy | M14: Delta Distribution for Home Appliances | N14: 21600 | O14: EGP | P14: 5 | Q14: Yes | R14: 2000000000107 | S14: 24 | T14: =S14*J14 -> 518400
A15: BTK-COM-011 | B15: Zanussi Front Load Washing Machine 7 Kg 1000 RPM ZWF70240S | C15: Washing Machines & Dishwashers | D15: Trading | E15: Goods | F15: Yes | G15: Serial | H15: Units | I15: 21000 | J15: 16800 | K15: =IF(I15>0,(I15-J15)/I15,"-") -> 0.2 | L15: Buy | M15: Delta Distribution for Home Appliances | N15: 16800 | O15: EGP | P15: 5 | Q15: Yes | R15: 2000000000114 | S15: 40 | T15: =S15*J15 -> 672000
A16: BTK-COM-012 | B16: Toshiba Top Load Washing Machine 10 Kg AEW-E1050SUP | C16: Washing Machines & Dishwashers | D16: Trading | E16: Goods | F16: Yes | G16: Serial | H16: Units | I16: 16800 | J16: 13450 | K16: =IF(I16>0,(I16-J16)/I16,"-") -> 0.19940476 | L16: Buy | M16: Egyptian Home Industries Agency | N16: 13450 | O16: EGP | P16: 5 | Q16: Yes | R16: 2000000000121 | S16: 32 | T16: =S16*J16 -> 430400
... A44: BTK-COM-040 | B44: Panasonic Vacuum Cleaner 2000W Drum Type MC-YL633 | C44: Small Appliances / Kitchen & Home Care | D44: Trading | E44: Goods | F44: Yes | G44: Serial | H44: Units | I44: 7800 | J44: 5750 | K44: =IF(I44>0,(I44-J44)/I44,"-") -> 0.26282051 | L44: Buy | M44: Nile Electronics Trading Co. | N44: 5750 | O44: EGP | P44: 4 | Q44: Yes | R44: 2000000000404 | S44: 40 | T44: =S44*J44 -> 230000
A45: BTK-MFG-001 | B45: Electronic Control PCB Board for Automatic Washer | C45: Manufactured / Electronics | D45: Manufactured | E45: Goods | F45: Yes | G45: - | H45: Units | I45: 1600 | J45: 856.5 | K45: =IF(I45>0,(I45-J45)/I45,"-") -> 0.4646875 | L45: Manufacture | M45: - | O45: - | Q45: No | R45: 2000000000411 | S45: 120 | T45: =S45*J45 -> 102780
A46: BTK-MFG-002 | B46: Refrigeration Wiring Harness Assembly | C46: Manufactured / Harnesses | D46: Manufactured | E46: Goods | F46: Yes | G46: - | H46: Units | I46: 650 | J46: 204 | K46: =IF(I46>0,(I46-J46)/I46,"-") -> 0.68615385 | L46: Manufacture | M46: - | O46: - | Q46: No | R46: 2000000000428 | S46: 200 | T46: =S46*J46 -> 40800
A47: BTK-MFG-003 | B47: Outdoor Metal Casing Body for 1.5 HP AC Unit | C47: Manufactured / Metal Casings | D47: Manufactured | E47: Goods | F47: Yes | G47: - | H47: Units | I47: 2500 | J47: 1377 | K47: =IF(I47>0,(I47-J47)/I47,"-") -> 0.4492 | L47: Manufacture | M47: - | O47: - | Q47: No | R47: 2000000000435 | S47: 85 | T47: =S47*J47 -> 117045
A48: BTK-MFG-004 | B48: Adjustable TV Wall Mount Bracket 32-65 Inch | C48: Manufactured / Accessories | D48: Manufactured | E48: Goods | F48: Yes | G48: - | H48: Units | I48: 580 | J48: 451 | K48: =IF(I48>0,(I48-J48)/I48,"-") -> 0.22241379 | L48: Manufacture | M48: - | O48: - | Q48: Yes | R48: 2000000000442 | S48: 300 | T48: =S48*J48 -> 135300
A49: BTK-MFG-005 | B49: Anti-Vibration Rubber Base Pad for Washing Machines | C49: Manufactured / Accessories | D49: Manufactured | E49: Goods | F49: Yes | G49: - | H49: Units | I49: 420 | J49: 170.67 | K49: =IF(I49>0,(I49-J49)/I49,"-") -> 0.59364286 | L49: Manufacture | M49: - | O49: - | Q49: Yes | R49: 2000000000459 | S49: 450 | T49: =S49*J49 -> 76801.5
A50: BTK-MFG-006 | B50: Power Distribution Unit & Surge Protector 6-Socket | C50: Manufactured / Power Units | D50: Manufactured | E50: Goods | F50: Yes | G50: - | H50: Units | I50: 950 | J50: 358 | K50: =IF(I50>0,(I50-J50)/I50,"-") -> 0.62315789 | L50: Manufacture | M50: - | O50: - | Q50: Yes | R50: 2000000000466 | S50: 180 | T50: =S50*J50 -> 64440
A51: BTK-MFG-007 | B51: Inverter Remote Fan Control Board | C51: Manufactured / Electronics | D51: Manufactured | E51: Goods | F51: Yes | G51: - | H51: Units | I51: 1100 | J51: 401.75 | K51: =IF(I51>0,(I51-J51)/I51,"-") -> 0.63477273 | L51: Manufacture | M51: - | O51: - | Q51: No | R51: 2000000000473 | S51: 140 | T51: =S51*J51 -> 56245
A52: BTK-MFG-008 | B52: Thermal Condenser Assembly for Home Appliances | C52: Manufactured / Components | D52: Manufactured | E52: Goods | F52: Yes | G52: - | H52: Units | I52: 1450 | J52: 1071 | K52: =IF(I52>0,(I52-J52)/I52,"-") -> 0.26137931 | L52: Manufacture | M52: - | O52: - | Q52: No | R52: 2000000000480 | S52: 95 | T52: =S52*J52 -> 101745
A53: BTK-MFG-009 | B53: Stainless Steel Gas Cooker Control Knob Box | C53: Manufactured / Metal Casings | D53: Manufactured | E53: Goods | F53: Yes | G53: - | H53: Units | I53: 1250 | J53: 630 | K53: =IF(I53>0,(I53-J53)/I53,"-") -> 0.496 | L53: Manufacture | M53: - | O53: - | Q53: No | R53: 2000000000497 | S53: 110 | T53: =S53*J53 -> 69300
A54: BTK-MFG-010 | B54: Desert Cooler Water Filter & Purification Unit | C54: Manufactured / Components | D54: Manufactured | E54: Goods | F54: Yes | G54: - | H54: Units | I54: 480 | J54: 234 | K54: =IF(I54>0,(I54-J54)/I54,"-") -> 0.5125 | L54: Manufacture | M54: - | O54: - | Q54: No | R54: 2000000000503 | S54: 250 | T54: =S54*J54 -> 58500
A55: BTK-MFG-011 | B55: Beitak Stand Fan 16 Inch with Remote Control | C55: Manufactured / Fans | D55: Manufactured | E55: Goods | F55: Yes | G55: Serial | H55: Units | I55: 2250 | J55: 1733.25 | K55: =IF(I55>0,(I55-J55)/I55,"-") -> 0.22966667 | L55: Manufacture | M55: - | O55: - | Q55: Yes | R55: 2000000000510 | S55: 60 | T55: =S55*J55 -> 103995
A56: BTK-RM-001 | B56: PCB Blank Board FR4 Double Layer | C56: Raw Materials / Electronic Components | D56: Raw Material | E56: Goods | F56: Yes | G56: - | H56: Units | I56: 0 | J56: 66 | K56: =IF(I56>0,(I56-J56)/I56,"-") -> - | L56: Buy | M56: Shenzhen Brightway Electronics Co., Ltd. | N56: 1.2 | O56: USD | P56: 45 | Q56: No | R56: - | S56: 600 | T56: =S56*J56 -> 39600
A57: BTK-RM-002 | B57: Electronic Components Kit - Fan Controller | C57: Raw Materials / Electronic Components | D57: Raw Material | E57: Goods | F57: Yes | G57: - | H57: Units | I57: 0 | J57: 192.5 | K57: =IF(I57>0,(I57-J57)/I57,"-") -> - | L57: Buy | M57: Shenzhen Brightway Electronics Co., Ltd. | N57: 3.5 | O57: USD | P57: 45 | Q57: No | R57: - | S57: 300 | T57: =S57*J57 -> 57750
A58: BTK-RM-003 | B58: Electronic Components Kit - Washer Controller | C58: Raw Materials / Electronic Components | D58: Raw Material | E58: Goods | F58: Yes | G58: - | H58: Units | I58: 0 | J58: 374 | K58: =IF(I58>0,(I58-J58)/I58,"-") -> - | L58: Buy | M58: Shenzhen Brightway Electronics Co., Ltd. | N58: 6.8 | O58: USD | P58: 45 | Q58: No | R58: - | S58: 200 | T58: =S58*J58 -> 74800
A59: BTK-RM-004 | B59: Relay Module 16A | C59: Raw Materials / Electronic Components | D59: Raw Material | E59: Goods | F59: Yes | G59: - | H59: Units | I59: 0 | J59: 49.5 | K59: =IF(I59>0,(I59-J59)/I59,"-") -> - | L59: Buy | M59: Shenzhen Brightway Electronics Co., Ltd. | N59: 0.9 | O59: USD | P59: 45 | Q59: No | R59: - | S59: 800 | T59: =S59*J59 -> 39600
A60: BTK-RM-005 | B60: Infrared Remote Control Unit | C60: Raw Materials / Electronic Components | D60: Raw Material | E60: Goods | F60: Yes | G60: - | H60: Units | I60: 0 | J60: 88 | K60: =IF(I60>0,(I60-J60)/I60,"-") -> - | L60: Buy | M60: Shenzhen Brightway Electronics Co., Ltd. | N60: 1.6 | O60: USD | P60: 45 | Q60: No | R60: - | S60: 300 | T60: =S60*J60 -> 26400
A61: BTK-RM-006 | B61: IR Receiver Module | C61: Raw Materials / Electronic Components | D61: Raw Material | E61: Goods | F61: Yes | G61: - | H61: Units | I61: 0 | J61: 19.25 | K61: =IF(I61>0,(I61-J61)/I61,"-") -> - | L61: Buy | M61: Shenzhen Brightway Electronics Co., Ltd. | N61: 0.35 | O61: USD | P61: 45 | Q61: No | R61: - | S61: 500 | T61: =S61*J61 -> 9625
A62: BTK-RM-007 | B62: Surge Protection Module (MOV) | C62: Raw Materials / Electronic Components | D62: Raw Material | E62: Goods | F62: Yes | G62: - | H62: Units | I62: 0 | J62: 44 | K62: =IF(I62>0,(I62-J62)/I62,"-") -> - | L62: Buy | M62: Shenzhen Brightway Electronics Co., Ltd. | N62: 0.8 | O62: USD | P62: 45 | Q62: No | R62: - | S62: 300 | T62: =S62*J62 -> 13200
A63: BTK-RM-008 | B63: Fan Motor 16 Inch 55W | C63: Raw Materials / Fan Parts | D63: Raw Material | E63: Goods | F63: Yes | G63: - | H63: Units | I63: 0 | J63: 522.5 | K63: =IF(I63>0,(I63-J63)/I63,"-") -> - | L63: Buy | M63: Ningbo Fanmotor Industrial Co., Ltd. | N63: 9.5 | O63: USD | P63: 50 | Q63: No | R63: - | S63: 200 | T63: =S63*J63 -> 104500
A64: BTK-RM-009 | B64: Fan Blade Set 16 Inch (3 Blades) | C64: Raw Materials / Fan Parts | D64: Raw Material | E64: Goods | F64: Yes | G64: - | H64: Units | I64: 0 | J64: 77 | K64: =IF(I64>0,(I64-J64)/I64,"-") -> - | L64: Buy | M64: Ningbo Fanmotor Industrial Co., Ltd. | N64: 1.4 | O64: USD | P64: 50 | Q64: No | R64: - | S64: 200 | T64: =S64*J64 -> 15400
A65: BTK-RM-010 | B65: Fan Safety Guard Set 16 Inch (Front & Rear) | C65: Raw Materials / Fan Parts | D65: Raw Material | E65: Goods | F65: Yes | G65: - | H65: Units | I65: 0 | J65: 115.5 | K65: =IF(I65>0,(I65-J65)/I65,"-") -> - | L65: Buy | M65: Ningbo Fanmotor Industrial Co., Ltd. | N65: 2.1 | O65: USD | P65: 50 | Q65: No | R65: - | S65: 200 | T65: =S65*J65 -> 23100
A66: BTK-RM-011 | B66: Fan Motor Housing Shell Set | C66: Raw Materials / Fan Parts | D66: Raw Material | E66: Goods | F66: Yes | G66: - | H66: Units | I66: 0 | J66: 71.5 | K66: =IF(I66>0,(I66-J66)/I66,"-") -> - | L66: Buy | M66: Ningbo Fanmotor Industrial Co., Ltd. | N66: 1.3 | O66: USD | P66: 50 | Q66: No | R66: - | S66: 200 | T66: =S66*J66 -> 14300
A67: BTK-RM-012 | B67: Galvanized Steel Sheet 1.0 mm | C67: Raw Materials / Metals | D67: Raw Material | E67: Goods | F67: Yes | G67: - | H67: kg | I67: 0 | J67: 70 | K67: =IF(I67>0,(I67-J67)/I67,"-") -> - | L67: Buy | M67: Egyptian Steel Sheets Co. | N67: 70 | O67: EGP | P67: 7 | Q67: No | R67: - | S67: 2500 | T67: =S67*J67 -> 175000
... A87: BTK-RM-032 | B87: User Manual & Warranty Card | C87: Raw Materials / Packaging & Fasteners | D87: Raw Material | E87: Goods | F87: Yes | G87: - | H87: Units | I87: 0 | J87: 4 | K87: =IF(I87>0,(I87-J87)/I87,"-") -> - | L87: Buy | M87: Cairo Packaging Co. | N87: 4 | O87: EGP | P87: 3 | Q87: No | R87: - | S87: 500 | T87: =S87*J87 -> 2000
...

Sheet Bills of Materials
A1: Bills of Materials
A2: 11 BOMs. BOM-MFG-007 (fan control board) is a sub-assembly used inside BOM-MFG-011 (Beitak Stand Fan) = multi-level BOM.
A4: BOM | B4: Finished Ref | C4: Finished Product | D4: Component Ref | E4: Component | F4: Qty per Unit | G4: UoM | H4: Unit Cost | I4: Line Cost
A5: BOM-MFG-007 | B5: BTK-MFG-007 | C5: Inverter Remote Fan Control Board | D5: BTK-RM-001 | E5: PCB Blank Board FR4 Double Layer | F5: 1 | G5: Units | H5: =INDEX(Products!$J$5:$J$93,MATCH(D5,Products!$A$5:$A$93,0)) -> 66 | I5: =F5*H5 -> 66
A6: BOM-MFG-007 | B6: BTK-MFG-007 | C6: Inverter Remote Fan Control Board | D6: BTK-RM-002 | E6: Electronic Components Kit - Fan Controller | F6: 1 | G6: Units | H6: =INDEX(Products!$J$5:$J$93,MATCH(D6,Products!$A$5:$A$93,0)) -> 192.5 | I6: =F6*H6 -> 192.5
A7: BOM-MFG-007 | B7: BTK-MFG-007 | C7: Inverter Remote Fan Control Board | D7: BTK-RM-006 | E7: IR Receiver Module | F7: 1 | G7: Units | H7: =INDEX(Products!$J$5:$J$93,MATCH(D7,Products!$A$5:$A$93,0)) -> 19.25 | I7: =F7*H7 -> 19.25
A8: BOM-MFG-007 | B8: BTK-MFG-007 | C8: Inverter Remote Fan Control Board | D8: BTK-RM-028 | E8: Solder Wire Tin-Lead | F8: 0.01 | G8: kg | H8: =INDEX(Products!$J$5:$J$93,MATCH(D8,Products!$A$5:$A$93,0)) -> 900 | I8: =F8*H8 -> 9
A9: BOM-MFG-001 | B9: BTK-MFG-001 | C9: Electronic Control PCB Board for Automatic Washer | D9: BTK-RM-001 | E9: PCB Blank Board FR4 Double Layer | F9: 1 | G9: Units | H9: =INDEX(Products!$J$5:$J$93,MATCH(D9,Products!$A$5:$A$93,0)) -> 66 | I9: =F9*H9 -> 66
A10: BOM-MFG-001 | B10: BTK-MFG-001 | C10: Electronic Control PCB Board for Automatic Washer | D10: BTK-RM-003 | E10: Electronic Components Kit - Washer Controller | F10: 1 | G10: Units | H10: =INDEX(Products!$J$5:$J$93,MATCH(D10,Products!$A$5:$A$93,0)) -> 374 | I10: =F10*H10 -> 374
A11: BOM-MFG-001 | B11: BTK-MFG-001 | C11: Electronic Control PCB Board for Automatic Washer | D11: BTK-RM-004 | E11: Relay Module 16A | F11: 4 | G11: Units | H11: =INDEX(Products!$J$5:$J$93,MATCH(D11,Products!$A$5:$A$93,0)) -> 49.5 | I11: =F11*H11 -> 198
A12: BOM-MFG-001 | B12: BTK-MFG-001 | C12: Electronic Control PCB Board for Automatic Washer | D12: BTK-RM-028 | E12: Solder Wire Tin-Lead | F12: 0.015 | G12: kg | H12: =INDEX(Products!$J$5:$J$93,MATCH(D12,Products!$A$5:$A$93,0)) -> 900 | I12: =F12*H12 -> 13.5
A13: BOM-MFG-002 | B13: BTK-MFG-002 | C13: Refrigeration Wiring Harness Assembly | D13: BTK-RM-023 | E13: Copper Wire 1.5 mm2 | F13: 6 | G13: m | H13: =INDEX(Products!$J$5:$J$93,MATCH(D13,Products!$A$5:$A$93,0)) -> 14 | I13: =F13*H13 -> 84
A14: BOM-MFG-002 | B14: BTK-MFG-002 | C14: Refrigeration Wiring Harness Assembly | D14: BTK-RM-025 | E14: Wire Connectors & Terminals Kit | F14: 1 | G14: Units | H14: =INDEX(Products!$J$5:$J$93,MATCH(D14,Products!$A$5:$A$93,0)) -> 25 | I14: =F14*H14 -> 25
A15: BOM-MFG-003 | B15: BTK-MFG-003 | C15: Outdoor Metal Casing Body for 1.5 HP AC Unit | D15: BTK-RM-012 | E15: Galvanized Steel Sheet 1.0 mm | F15: 12 | G15: kg | H15: =INDEX(Products!$J$5:$J$93,MATCH(D15,Products!$A$5:$A$93,0)) -> 70 | I15: =F15*H15 -> 840
A16: BOM-MFG-003 | B16: BTK-MFG-003 | C16: Outdoor Metal Casing Body for 1.5 HP AC Unit | D16: BTK-RM-014 | E16: Powder Coating Paint | F16: 0.6 | G16: kg | H16: =INDEX(Products!$J$5:$J$93,MATCH(D16,Products!$A$5:$A$93,0)) -> 220 | I16: =F16*H16 -> 132
... A50: BOM-MFG-011 | B50: BTK-MFG-011 | C50: Beitak Stand Fan 16 Inch with Remote Control | D50: BTK-RM-032 | E50: User Manual & Warranty Card | F50: 1 | G50: Units | H50: =INDEX(Products!$J$5:$J$93,MATCH(D50,Products!$A$5:$A$93,0)) -> 4 | I50: =F50*H50 -> 4

Sheet Work Centers
A1: Work Centers
A2: Cost per hour feeds the manufacturing cost (setup and cleanup time = 0).
A4: Code | B4: Work Center | C4: Cost per Hour (EGP) | D4: Time Efficiency | E4: OEE Target
A5: ASM1 | B5: Assembly Line 1 | C5: 240 | D5: 1 | E5: 0.85
A6: ELEC | B6: Electronics & PCB Station | C6: 300 | D6: 1 | E6: 0.85
A7: METAL | B7: Metal Fabrication & Painting | C7: 360 | D7: 1 | E7: 0.85
A8: MOLD | B8: Rubber & Plastic Molding | C8: 200 | D8: 1 | E8: 0.85
A9: QCPK | B9: Quality Control & Packing | C9: 180 | D9: 1 | E9: 0.85

Sheet Operations
A1: BOM Operations (Routing)
A2: Work orders per BOM; minutes per unit.
A4: BOM | B4: Sequence | C4: Operation | D4: Work Center | E4: Minutes per Unit | F4: Cost per Hour | G4: Cost per Unit
A5: BOM-MFG-007 | B5: 10 | C5: SMT soldering & assembly | D5: ELEC | E5: 20 | F5: =INDEX('Work Centers'!$C$5:$C$9,MATCH(D5,'Work Centers'!$A$5:$A$9,0)) -> 300 | G5: =E5/60*F5 -> 100
A6: BOM-MFG-007 | B6: 20 | C6: Functional test | D6: QCPK | E6: 5 | F6: =INDEX('Work Centers'!$C$5:$C$9,MATCH(D6,'Work Centers'!$A$5:$A$9,0)) -> 180 | G6: =E6/60*F6 -> 15
A7: BOM-MFG-001 | B7: 10 | C7: SMT soldering & relay mounting | D7: ELEC | E7: 35 | F7: =INDEX('Work Centers'!$C$5:$C$9,MATCH(D7,'Work Centers'!$A$5:$A$9,0)) -> 300 | G7: =E7/60*F7 -> 175
A8: BOM-MFG-001 | B8: 20 | C8: Functional test | D8: QCPK | E8: 10 | F8: =INDEX('Work Centers'!$C$5:$C$9,MATCH(D8,'Work Centers'!$A$5:$A$9,0)) -> 180 | G8: =E8/60*F8 -> 30
A9: BOM-MFG-002 | B9: 10 | C9: Cutting, crimping & harness assembly | D9: ASM1 | E9: 20 | F9: =INDEX('Work Centers'!$C$5:$C$9,MATCH(D9,'Work Centers'!$A$5:$A$9,0)) -> 240 | G9: =E9/60*F9 -> 80
A10: BOM-MFG-002 | B10: 20 | C10: Continuity test | D10: QCPK | E10: 5 | F10: =INDEX('Work Centers'!$C$5:$C$9,MATCH(D10,'Work Centers'!$A$5:$A$9,0)) -> 180 | G10: =E10/60*F10 -> 15
A11: BOM-MFG-003 | B11: 10 | C11: Cutting, bending & powder coating | D11: METAL | E11: 60 | F11: =INDEX('Work Centers'!$C$5:$C$9,MATCH(D11,'Work Centers'!$A$5:$A$9,0)) -> 360 | G11: =E11/60*F11 -> 360
A12: BOM-MFG-003 | B12: 20 | C12: Inspection & packing | D12: QCPK | E12: 10 | F12: =INDEX('Work Centers'!$C$5:$C$9,MATCH(D12,'Work Centers'!$A$5:$A$9,0)) -> 180 | G12: =E12/60*F12 -> 30
A13: BOM-MFG-004 | B13: 10 | C13: Cutting, bending & powder coating | D13: METAL | E13: 20 | F13: =INDEX('Work Centers'!$C$5:$C$9,MATCH(D13,'Work Centers'!$A$5:$A$9,0)) -> 360 | G13: =E13/60*F13 -> 120
A14: BOM-MFG-004 | B14: 20 | C14: Inspection & packing | D14: QCPK | E14: 5 | F14: =INDEX('Work Centers'!$C$5:$C$9,MATCH(D14,'Work Centers'!$A$5:$A$9,0)) -> 180 | G14: =E14/60*F14 -> 15
A15: BOM-MFG-005 | B15: 10 | C15: Rubber molding & curing | D15: MOLD | E15: 8 | F15: =INDEX('Work Centers'!$C$5:$C$9,MATCH(D15,'Work Centers'!$A$5:$A$9,0)) -> 200 | G15: =E15/60*F15 -> 26.666667
A16: BOM-MFG-006 | B16: 10 | C16: Wiring & assembly | D16: ELEC | E16: 15 | F16: =INDEX('Work Centers'!$C$5:$C$9,MATCH(D16,'Work Centers'!$A$5:$A$9,0)) -> 300 | G16: =E16/60*F16 -> 75
... A25: BOM-MFG-011 | B25: 20 | C25: Run test, QC & packing | D25: QCPK | E25: 10 | F25: =INDEX('Work Centers'!$C$5:$C$9,MATCH(D25,'Work Centers'!$A$5:$A$9,0)) -> 180 | G25: =E25/60*F25 -> 30

Sheet BOM Cost Summary
A1: Manufactured Cost Roll-up
A2: Total BOM cost must equal the product cost loaded in Odoo (difference = 0). Sub-assembly cost flows into the fan.
A4: BOM | B4: Product Ref | C4: Product | D4: Components Cost | E4: Operations Cost | F4: Total BOM Cost | G4: Cost in Products | H4: Difference
A5: BOM-MFG-007 | B5: BTK-MFG-007 | C5: Inverter Remote Fan Control Board | D5: =SUMIF('Bills of Materials'!$A$5:$A$50,A5,'Bills of Materials'!$I$5:$I$50) -> 286.75 | E5: =SUMIF(Operations!$A$5:$A$25,A5,Operations!$G$5:$G$25) -> 115 | F5: =D5+E5 -> 401.75 | G5: =INDEX(Products!$J$5:$J$93,MATCH(B5,Products!$A$5:$A$93,0)) -> 401.75 | H5: =ROUND(F5-G5,2) -> 0
A6: BOM-MFG-001 | B6: BTK-MFG-001 | C6: Electronic Control PCB Board for Automatic Washer | D6: =SUMIF('Bills of Materials'!$A$5:$A$50,A6,'Bills of Materials'!$I$5:$I$50) -> 651.5 | E6: =SUMIF(Operations!$A$5:$A$25,A6,Operations!$G$5:$G$25) -> 205 | F6: =D6+E6 -> 856.5 | G6: =INDEX(Products!$J$5:$J$93,MATCH(B6,Products!$A$5:$A$93,0)) -> 856.5 | H6: =ROUND(F6-G6,2) -> 0
A7: BOM-MFG-002 | B7: BTK-MFG-002 | C7: Refrigeration Wiring Harness Assembly | D7: =SUMIF('Bills of Materials'!$A$5:$A$50,A7,'Bills of Materials'!$I$5:$I$50) -> 109 | E7: =SUMIF(Operations!$A$5:$A$25,A7,Operations!$G$5:$G$25) -> 95 | F7: =D7+E7 -> 204 | G7: =INDEX(Products!$J$5:$J$93,MATCH(B7,Products!$A$5:$A$93,0)) -> 204 | H7: =ROUND(F7-G7,2) -> 0
A8: BOM-MFG-003 | B8: BTK-MFG-003 | C8: Outdoor Metal Casing Body for 1.5 HP AC Unit | D8: =SUMIF('Bills of Materials'!$A$5:$A$50,A8,'Bills of Materials'!$I$5:$I$50) -> 987 | E8: =SUMIF(Operations!$A$5:$A$25,A8,Operations!$G$5:$G$25) -> 390 | F8: =D8+E8 -> 1377 | G8: =INDEX(Products!$J$5:$J$93,MATCH(B8,Products!$A$5:$A$93,0)) -> 1377 | H8: =ROUND(F8-G8,2) -> 0
A9: BOM-MFG-004 | B9: BTK-MFG-004 | C9: Adjustable TV Wall Mount Bracket 32-65 Inch | D9: =SUMIF('Bills of Materials'!$A$5:$A$50,A9,'Bills of Materials'!$I$5:$I$50) -> 316 | E9: =SUMIF(Operations!$A$5:$A$25,A9,Operations!$G$5:$G$25) -> 135 | F9: =D9+E9 -> 451 | G9: =INDEX(Products!$J$5:$J$93,MATCH(B9,Products!$A$5:$A$93,0)) -> 451 | H9: =ROUND(F9-G9,2) -> 0
A10: BOM-MFG-005 | B10: BTK-MFG-005 | C10: Anti-Vibration Rubber Base Pad for Washing Machines | D10: =SUMIF('Bills of Materials'!$A$5:$A$50,A10,'Bills of Materials'!$I$5:$I$50) -> 144 | E10: =SUMIF(Operations!$A$5:$A$25,A10,Operations!$G$5:$G$25) -> 26.666667 | F10: =D10+E10 -> 170.66667 | G10: =INDEX(Products!$J$5:$J$93,MATCH(B10,Products!$A$5:$A$93,0)) -> 170.67 | H10: =ROUND(F10-G10,2) -> 0
A11: BOM-MFG-006 | B11: BTK-MFG-006 | C11: Power Distribution Unit & Surge Protector 6-Socket | D11: =SUMIF('Bills of Materials'!$A$5:$A$50,A11,'Bills of Materials'!$I$5:$I$50) -> 268 | E11: =SUMIF(Operations!$A$5:$A$25,A11,Operations!$G$5:$G$25) -> 90 | F11: =D11+E11 -> 358 | G11: =INDEX(Products!$J$5:$J$93,MATCH(B11,Products!$A$5:$A$93,0)) -> 358 | H11: =ROUND(F11-G11,2) -> 0
A12: BOM-MFG-008 | B12: BTK-MFG-008 | C12: Thermal Condenser Assembly for Home Appliances | D12: =SUMIF('Bills of Materials'!$A$5:$A$50,A12,'Bills of Materials'!$I$5:$I$50) -> 906 | E12: =SUMIF(Operations!$A$5:$A$25,A12,Operations!$G$5:$G$25) -> 165 | F12: =D12+E12 -> 1071 | G12: =INDEX(Products!$J$5:$J$93,MATCH(B12,Products!$A$5:$A$93,0)) -> 1071 | H12: =ROUND(F12-G12,2) -> 0
A13: BOM-MFG-009 | B13: BTK-MFG-009 | C13: Stainless Steel Gas Cooker Control Knob Box | D13: =SUMIF('Bills of Materials'!$A$5:$A$50,A13,'Bills of Materials'!$I$5:$I$50) -> 435 | E13: =SUMIF(Operations!$A$5:$A$25,A13,Operations!$G$5:$G$25) -> 195 | F13: =D13+E13 -> 630 | G13: =INDEX(Products!$J$5:$J$93,MATCH(B13,Products!$A$5:$A$93,0)) -> 630 | H13: =ROUND(F13-G13,2) -> 0
A14: BOM-MFG-010 | B14: BTK-MFG-010 | C14: Desert Cooler Water Filter & Purification Unit | D14: =SUMIF('Bills of Materials'!$A$5:$A$50,A14,'Bills of Materials'!$I$5:$I$50) -> 179 | E14: =SUMIF(Operations!$A$5:$A$25,A14,Operations!$G$5:$G$25) -> 55 | F14: =D14+E14 -> 234 | G14: =INDEX(Products!$J$5:$J$93,MATCH(B14,Products!$A$5:$A$93,0)) -> 234 | H14: =ROUND(F14-G14,2) -> 0
A15: BOM-MFG-011 | B15: BTK-MFG-011 | C15: Beitak Stand Fan 16 Inch with Remote Control | D15: =SUMIF('Bills of Materials'!$A$5:$A$50,A15,'Bills of Materials'!$I$5:$I$50) -> 1583.25 | E15: =SUMIF(Operations!$A$5:$A$25,A15,Operations!$G$5:$G$25) -> 150 | F15: =D15+E15 -> 1733.25 | G15: =INDEX(Products!$J$5:$J$93,MATCH(B15,Products!$A$5:$A$93,0)) -> 1733.25 | H15: =ROUND(F15-G15,2) -> 0

Sheet Price Lists
A1: Price Lists
A2: Example: LG Smart TV 50 Inch (BTK-COM-030), list price 19,200 EGP excl. VAT.
A4: Price List | B4: Rule | C4: Discount | D4: Min Qty | E4: Description | F4: Example List Price | G4: Example Net Price
A5: Retail - Showroom | B5: List price | C5: 0 | D5: 1 | E5: Public price (list price). Used by POS and walk-in customers. | F5: 19200 | G5: =F5*(1-C5) -> 19200
A6: Wholesale - Retailers | B6: 5% discount | C6: 0.05 | D6: 1 | E6: 5% off list price; 7% off from 10 units per line. | F6: 19200 | G6: =F6*(1-C6) -> 18240
A7: Wholesale - Retailers | B7: 7% discount | C7: 0.07 | D7: 10 | E7: 5% off list price; 7% off from 10 units per line. | F7: 19200 | G7: =F7*(1-C7) -> 17856
A8: Distributors | B8: 10% discount | C8: 0.1 | D8: 1 | E8: 10% off list price; 12% off from 20 units per line. | F8: 19200 | G8: =F8*(1-C8) -> 17280
A9: Distributors | B9: 12% discount | C9: 0.12 | D9: 20 | E9: 10% off list price; 12% off from 20 units per line. | F9: 19200 | G9: =F9*(1-C9) -> 16896
A10: Key Accounts & Corporate | B10: 7% discount | C10: 0.07 | D10: 1 | E10: 7% off list price on all products. | F10: 19200 | G10: =F10*(1-C10) -> 17856

Sheet Warehouses
A1: Warehouses, Routes and Operations
A2: Branches are resupplied from Cairo (inter-warehouse route). Manufacturing happens only in Cairo.
A4: Warehouse | B4: Code | C4: Address | D4: Receipt Steps | E4: Delivery Steps | F4: Manufacture | G4: Resupplied From | H4: Role
A5: Cairo Warehouse (Main) | B5: CAW | C5: El Obour Industrial Zone, Block 12, Cairo | D5: 3 steps: Input > Quality Control > Stock | E5: 3 steps: Pick > Pack > Ship | F5: Yes | G5: Vendors (Buy) | H5: Showroom + production
A6: Alexandria Warehouse | B6: ALW | C6: Borg El Arab Industrial Zone, Alexandria | D6: 1 step: directly to Stock | E6: 2 steps: Pick > Ship | F6: No | G6: Cairo Warehouse (Main) | H6: Regional distribution
A7: Mansoura Warehouse | B7: MAW | C7: Talkha Road, Mansoura | D7: 1 step: directly to Stock | E7: 2 steps: Pick > Ship | F7: No | G7: Cairo Warehouse (Main) | H7: Regional distribution
A8: Ismailia Warehouse | B8: ISW | C8: Ismailia Industrial Zone, Ismailia | D8: 1 step: directly to Stock | E8: 2 steps: Pick > Ship | F8: No | G8: Cairo Warehouse (Main) | H8: Regional distribution
A9: Asyut Warehouse | B9: ASW | C9: Arab El Awamer Industrial Zone, Asyut | D9: 1 step: directly to Stock | E9: 2 steps: Pick > Ship | F9: No | G9: Cairo Warehouse (Main) | H9: Regional distribution

Sheet Locations
A1: Inventory Locations
A2: Step locations are created by Odoo from the warehouse settings and are not imported.
A4: Location | B4: Warehouse | C4: Type | D4: Origin | E4: Purpose
A5: CAW/Stock | B5: Cairo Warehouse (Main) | C5: Internal | D5: Created by Odoo | E5: Main stock location
A6: CAW/Input | B6: Cairo Warehouse (Main) | C6: Internal | D6: Created by Odoo | E6: Warehouse step location
A7: CAW/Quality Control | B7: Cairo Warehouse (Main) | C7: Internal | D7: Created by Odoo | E7: Warehouse step location
A8: CAW/Output | B8: Cairo Warehouse (Main) | C8: Internal | D8: Created by Odoo | E8: Warehouse step location
A9: CAW/Packing Zone | B9: Cairo Warehouse (Main) | C9: Internal | D9: Created by Odoo | E9: Warehouse step location
A10: CAW/Stock/First Floor - Large Appliances | B10: Cairo Warehouse (Main) | C10: Internal | D10: Imported (22_Locations) | E10: Large appliances storage
A11: CAW/Stock/Second Floor - Small Appliances | B11: Cairo Warehouse (Main) | C11: Internal | D11: Imported (22_Locations) | E11: Small appliances, TVs, fans storage
A12: CAW/Stock/Raw Materials Store | B12: Cairo Warehouse (Main) | C12: Internal | D12: Imported (22_Locations) | E12: Raw materials for production (new)
A13: CAW/Stock/Finished Goods - Manufactured | B13: Cairo Warehouse (Main) | C13: Internal | D13: Imported (22_Locations) | E13: Output of manufacturing orders (new)
A14: CAW/Stock/Showroom Display | B14: Cairo Warehouse (Main) | C14: Internal | D14: Imported (22_Locations) | E14: Cairo showroom stock sold through POS (new)
A15: ALW/Stock | B15: Alexandria Warehouse | C15: Internal | D15: Created by Odoo | E15: Main stock location
... A30: ASW/Stock/Second Floor - Small Appliances | B30: Asyut Warehouse | C30: Internal | D30: Imported (22_Locations) | E30: Small appliances, TVs, fans storage

Sheet Stock by Location
A1: Opening Stock by Product and Location
A2: Imported with 24_Opening_Stock.xlsx (serial-tracked products expand to one line per serial). Accounting date 2027-01-01.
A4: Internal Ref | B4: Product | C4: Category | D4: Inventory Acc. | E4: Warehouse | F4: Location | G4: Qty | H4: Unit Cost | I4: Value
A5: BTK-COM-001 | B5: Sharp Refrigerator 18 Cu. Ft. No-Frost Stainless SJ-GV58G-SL | C5: Refrigerators & Freezers | D5: 120100 | E5: CAW | F5: CAW/Stock/First Floor - Large Appliances | G5: 9 | H5: =INDEX(Products!$J$5:$J$93,MATCH(A5,Products!$A$5:$A$93,0)) -> 26400 | I5: =G5*H5 -> 237600
A6: BTK-COM-001 | B6: Sharp Refrigerator 18 Cu. Ft. No-Frost Stainless SJ-GV58G-SL | C6: Refrigerators & Freezers | D6: 120100 | E6: ALW | F6: ALW/Stock/First Floor - Large Appliances | G6: 5 | H6: =INDEX(Products!$J$5:$J$93,MATCH(A6,Products!$A$5:$A$93,0)) -> 26400 | I6: =G6*H6 -> 132000
A7: BTK-COM-001 | B7: Sharp Refrigerator 18 Cu. Ft. No-Frost Stainless SJ-GV58G-SL | C7: Refrigerators & Freezers | D7: 120100 | E7: MAW | F7: MAW/Stock/First Floor - Large Appliances | G7: 4 | H7: =INDEX(Products!$J$5:$J$93,MATCH(A7,Products!$A$5:$A$93,0)) -> 26400 | I7: =G7*H7 -> 105600
A8: BTK-COM-001 | B8: Sharp Refrigerator 18 Cu. Ft. No-Frost Stainless SJ-GV58G-SL | C8: Refrigerators & Freezers | D8: 120100 | E8: ISW | F8: ISW/Stock/First Floor - Large Appliances | G8: 3 | H8: =INDEX(Products!$J$5:$J$93,MATCH(A8,Products!$A$5:$A$93,0)) -> 26400 | I8: =G8*H8 -> 79200
A9: BTK-COM-001 | B9: Sharp Refrigerator 18 Cu. Ft. No-Frost Stainless SJ-GV58G-SL | C9: Refrigerators & Freezers | D9: 120100 | E9: ASW | F9: ASW/Stock/First Floor - Large Appliances | G9: 4 | H9: =INDEX(Products!$J$5:$J$93,MATCH(A9,Products!$A$5:$A$93,0)) -> 26400 | I9: =G9*H9 -> 105600
A10: BTK-COM-002 | B10: LG Refrigerator 20 Cu. Ft. Digital Inverter GN-B5722HLHU | C10: Refrigerators & Freezers | D10: 120100 | E10: CAW | F10: CAW/Stock/First Floor - Large Appliances | G10: 6 | H10: =INDEX(Products!$J$5:$J$93,MATCH(A10,Products!$A$5:$A$93,0)) -> 33600 | I10: =G10*H10 -> 201600
A11: BTK-COM-002 | B11: LG Refrigerator 20 Cu. Ft. Digital Inverter GN-B5722HLHU | C11: Refrigerators & Freezers | D11: 120100 | E11: ALW | F11: ALW/Stock/First Floor - Large Appliances | G11: 4 | H11: =INDEX(Products!$J$5:$J$93,MATCH(A11,Products!$A$5:$A$93,0)) -> 33600 | I11: =G11*H11 -> 134400
A12: BTK-COM-002 | B12: LG Refrigerator 20 Cu. Ft. Digital Inverter GN-B5722HLHU | C12: Refrigerators & Freezers | D12: 120100 | E12: MAW | F12: MAW/Stock/First Floor - Large Appliances | G12: 3 | H12: =INDEX(Products!$J$5:$J$93,MATCH(A12,Products!$A$5:$A$93,0)) -> 33600 | I12: =G12*H12 -> 100800
A13: BTK-COM-002 | B13: LG Refrigerator 20 Cu. Ft. Digital Inverter GN-B5722HLHU | C13: Refrigerators & Freezers | D13: 120100 | E13: ISW | F13: ISW/Stock/First Floor - Large Appliances | G13: 2 | H13: =INDEX(Products!$J$5:$J$93,MATCH(A13,Products!$A$5:$A$93,0)) -> 33600 | I13: =G13*H13 -> 67200
A14: BTK-COM-002 | B14: LG Refrigerator 20 Cu. Ft. Digital Inverter GN-B5722HLHU | C14: Refrigerators & Freezers | D14: 120100 | E14: ASW | F14: ASW/Stock/First Floor - Large Appliances | G14: 3 | H14: =INDEX(Products!$J$5:$J$93,MATCH(A14,Products!$A$5:$A$93,0)) -> 33600 | I14: =G14*H14 -> 100800
A15: BTK-COM-003 | B15: Samsung Refrigerator 22 Cu. Ft. Side-by-Side RS62R5001M9 | C15: Refrigerators & Freezers | D15: 120100 | E15: CAW | F15: CAW/Stock/First Floor - Large Appliances | G15: 4 | H15: =INDEX(Products!$J$5:$J$93,MATCH(A15,Products!$A$5:$A$93,0)) -> 57600 | I15: =G15*H15 -> 230400
A16: BTK-COM-003 | B16: Samsung Refrigerator 22 Cu. Ft. Side-by-Side RS62R5001M9 | C16: Refrigerators & Freezers | D16: 120100 | E16: ALW | F16: ALW/Stock/First Floor - Large Appliances | G16: 2 | H16: =INDEX(Products!$J$5:$J$93,MATCH(A16,Products!$A$5:$A$93,0)) -> 57600 | I16: =G16*H16 -> 115200
... A264: BTK-RM-032 | B264: User Manual & Warranty Card | C264: Raw Materials / Packaging & Fasteners | D264: 120800 | E264: CAW | F264: CAW/Stock/Raw Materials Store | G264: 500 | H264: =INDEX(Products!$J$5:$J$93,MATCH(A264,Products!$A$5:$A$93,0)) -> 4 | I264: =G264*H264 -> 2000
A265: Total | G265: =SUM(G5:G264) -> 24746 | I265: =SUM(I5:I264) -> 20424776

Sheet Stock by Warehouse
A1: Opening Stock by Warehouse
A2: SUMIFS from 'Stock by Location'. Column headers are the warehouse codes.
A4: Internal Ref | B4: Product | C4: CAW | D4: ALW | E4: MAW | F4: ISW | G4: ASW | H4: Total Qty | I4: Unit Cost | J4: Value
A5: BTK-COM-001 | B5: Sharp Refrigerator 18 Cu. Ft. No-Frost Stainless SJ-GV58G-SL | C5: =SUMIFS('Stock by Location'!$G$5:$G$264,'Stock by Location'!$A$5:$A$264,$A5,'Stock by Location'!$E$5:$E$264,C$4) -> 9 | D5: =SUMIFS('Stock by Location'!$G$5:$G$264,'Stock by Location'!$A$5:$A$264,$A5,'Stock by Location'!$E$5:$E$264,D$4) -> 5 | E5: =SUMIFS('Stock by Location'!$G$5:$G$264,'Stock by Location'!$A$5:$A$264,$A5,'Stock by Location'!$E$5:$E$264,E$4) -> 4 | F5: =SUMIFS('Stock by Location'!$G$5:$G$264,'Stock by Location'!$A$5:$A$264,$A5,'Stock by Location'!$E$5:$E$264,F$4) -> 3 | G5: =SUMIFS('Stock by Location'!$G$5:$G$264,'Stock by Location'!$A$5:$A$264,$A5,'Stock by Location'!$E$5:$E$264,G$4) -> 4 | H5: =SUM(C5:G5) -> 25 | I5: =INDEX(Products!$J$5:$J$93,MATCH(A5,Products!$A$5:$A$93,0)) -> 26400 | J5: =H5*I5 -> 660000
A6: BTK-COM-002 | B6: LG Refrigerator 20 Cu. Ft. Digital Inverter GN-B5722HLHU | C6: =SUMIFS('Stock by Location'!$G$5:$G$264,'Stock by Location'!$A$5:$A$264,$A6,'Stock by Location'!$E$5:$E$264,C$4) -> 6 | D6: =SUMIFS('Stock by Location'!$G$5:$G$264,'Stock by Location'!$A$5:$A$264,$A6,'Stock by Location'!$E$5:$E$264,D$4) -> 4 | E6: =SUMIFS('Stock by Location'!$G$5:$G$264,'Stock by Location'!$A$5:$A$264,$A6,'Stock by Location'!$E$5:$E$264,E$4) -> 3 | F6: =SUMIFS('Stock by Location'!$G$5:$G$264,'Stock by Location'!$A$5:$A$264,$A6,'Stock by Location'!$E$5:$E$264,F$4) -> 2 | G6: =SUMIFS('Stock by Location'!$G$5:$G$264,'Stock by Location'!$A$5:$A$264,$A6,'Stock by Location'!$E$5:$E$264,G$4) -> 3 | H6: =SUM(C6:G6) -> 18 | I6: =INDEX(Products!$J$5:$J$93,MATCH(A6,Products!$A$5:$A$93,0)) -> 33600 | J6: =H6*I6 -> 604800
A7: BTK-COM-003 | B7: Samsung Refrigerator 22 Cu. Ft. Side-by-Side RS62R5001M9 | C7: =SUMIFS('Stock by Location'!$G$5:$G$264,'Stock by Location'!$A$5:$A$264,$A7,'Stock by Location'!$E$5:$E$264,C$4) -> 4 | D7: =SUMIFS('Stock by Location'!$G$5:$G$264,'Stock by Location'!$A$5:$A$264,$A7,'Stock by Location'!$E$5:$E$264,D$4) -> 2 | E7: =SUMIFS('Stock by Location'!$G$5:$G$264,'Stock by Location'!$A$5:$A$264,$A7,'Stock by Location'!$E$5:$E$264,E$4) -> 2 | F7: =SUMIFS('Stock by Location'!$G$5:$G$264,'Stock by Location'!$A$5:$A$264,$A7,'Stock by Location'!$E$5:$E$264,F$4) -> 2 | G7: =SUMIFS('Stock by Location'!$G$5:$G$264,'Stock by Location'!$A$5:$A$264,$A7,'Stock by Location'!$E$5:$E$264,G$4) -> 2 | H7: =SUM(C7:G7) -> 12 | I7: =INDEX(Products!$J$5:$J$93,MATCH(A7,Products!$A$5:$A$93,0)) -> 57600 | J7: =H7*I7 -> 691200
A8: BTK-COM-004 | B8: Tornado Refrigerator 14 Cu. Ft. No-Frost RF-48T-SL | C8: =SUMIFS('Stock by Location'!$G$5:$G$264,'Stock by Location'!$A$5:$A$264,$A8,'Stock by Location'!$E$5:$E$264,C$4) -> 11 | D8: =SUMIFS('Stock by Location'!$G$5:$G$264,'Stock by Location'!$A$5:$A$264,$A8,'Stock by Location'!$E$5:$E$264,D$4) -> 6 | E8: =SUMIFS('Stock by Location'!$G$5:$G$264,'Stock by Location'!$A$5:$A$264,$A8,'Stock by Location'!$E$5:$E$264,E$4) -> 5 | F8: =SUMIFS('Stock by Location'!$G$5:$G$264,'Stock by Location'!$A$5:$A$264,$A8,'Stock by Location'!$E$5:$E$264,F$4) -> 4 | G8: =SUMIFS('Stock by Location'!$G$5:$G$264,'Stock by Location'!$A$5:$A$264,$A8,'Stock by Location'!$E$5:$E$264,G$4) -> 4 | H8: =SUM(C8:G8) -> 30 | I8: =INDEX(Products!$J$5:$J$93,MATCH(A8,Products!$A$5:$A$93,0)) -> 18800 | J8: =H8*I8 -> 564000
A9: BTK-COM-005 | B9: Kiriazi Refrigerator 16 Cu. Ft. Zomoroda No-Frost K330 | C9: =SUMIFS('Stock by Location'!$G$5:$G$264,'Stock by Location'!$A$5:$A$264,$A9,'Stock by Location'!$E$5:$E$264,C$4) -> 7 | D9: =SUMIFS('Stock by Location'!$G$5:$G$264,'Stock by Location'!$A$5:$A$264,$A9,'Stock by Location'!$E$5:$E$264,D$4) -> 4 | E9: =SUMIFS('Stock by Location'!$G$5:$G$264,'Stock by Location'!$A$5:$A$264,$A9,'Stock by Location'!$E$5:$E$264,E$4) -> 4 | F9: =SUMIFS('Stock by Location'!$G$5:$G$264,'Stock by Location'!$A$5:$A$264,$A9,'Stock by Location'!$E$5:$E$264,F$4) -> 2 | G9: =SUMIFS('Stock by Location'!$G$5:$G$264,'Stock by Location'!$A$5:$A$264,$A9,'Stock by Location'!$E$5:$E$264,G$4) -> 3 | H9: =SUM(C9:G9) -> 20 | I9: =INDEX(Products!$J$5:$J$93,MATCH(A9,Products!$A$5:$A$93,0)) -> 21200 | J9: =H9*I9 -> 424000
A10: BTK-COM-006 | B10: Toshiba Deep Freezer 5 Drawers No-Frost GF-18H-S | C10: =SUMIFS('Stock by Location'!$G$5:$G$264,'Stock by Location'!$A$5:$A$264,$A10,'Stock by Location'!$E$5:$E$264,C$4) -> 12 | D10: =SUMIFS('Stock by Location'!$G$5:$G$264,'Stock by Location'!$A$5:$A$264,$A10,'Stock by Location'!$E$5:$E$264,D$4) -> 7 | E10: =SUMIFS('Stock by Location'!$G$5:$G$264,'Stock by Location'!$A$5:$A$264,$A10,'Stock by Location'!$E$5:$E$264,E$4) -> 7 | F10: =SUMIFS('Stock by Location'!$G$5:$G$264,'Stock by Location'!$A$5:$A$264,$A10,'Stock by Location'!$E$5:$E$264,F$4) -> 4 | G10: =SUMIFS('Stock by Location'!$G$5:$G$264,'Stock by Location'!$A$5:$A$264,$A10,'Stock by Location'!$E$5:$E$264,G$4) -> 5 | H10: =SUM(C10:G10) -> 35 | I10: =INDEX(Products!$J$5:$J$93,MATCH(A10,Products!$A$5:$A$93,0)) -> 18000 | J10: =H10*I10 -> 630000
A11: BTK-COM-007 | B11: Beko Upright Deep Freezer 7 Drawers RFNE260E13S | C11: =SUMIFS('Stock by Location'!$G$5:$G$264,'Stock by Location'!$A$5:$A$264,$A11,'Stock by Location'!$E$5:$E$264,C$4) -> 5 | D11: =SUMIFS('Stock by Location'!$G$5:$G$264,'Stock by Location'!$A$5:$A$264,$A11,'Stock by Location'!$E$5:$E$264,D$4) -> 3 | E11: =SUMIFS('Stock by Location'!$G$5:$G$264,'Stock by Location'!$A$5:$A$264,$A11,'Stock by Location'!$E$5:$E$264,E$4) -> 3 | F11: =SUMIFS('Stock by Location'!$G$5:$G$264,'Stock by Location'!$A$5:$A$264,$A11,'Stock by Location'!$E$5:$E$264,F$4) -> 2 | G11: =SUMIFS('Stock by Location'!$G$5:$G$264,'Stock by Location'!$A$5:$A$264,$A11,'Stock by Location'!$E$5:$E$264,G$4) -> 2 | H11: =SUM(C11:G11) -> 15 | I11: =INDEX(Products!$J$5:$J$93,MATCH(A11,Products!$A$5:$A$93,0)) -> 23600 | J11: =H11*I11 -> 354000
A12: BTK-COM-008 | B12: Kiriazi Deep Freezer 4 Drawers E220 | C12: =SUMIFS('Stock by Location'!$G$5:$G$264,'Stock by Location'!$A$5:$A$264,$A12,'Stock by Location'!$E$5:$E$264,C$4) -> 8 | D12: =SUMIFS('Stock by Location'!$G$5:$G$264,'Stock by Location'!$A$5:$A$264,$A12,'Stock by Location'!$E$5:$E$264,D$4) -> 4 | E12: =SUMIFS('Stock by Location'!$G$5:$G$264,'Stock by Location'!$A$5:$A$264,$A12,'Stock by Location'!$E$5:$E$264,E$4) -> 4 | F12: =SUMIFS('Stock by Location'!$G$5:$G$264,'Stock by Location'!$A$5:$A$264,$A12,'Stock by Location'!$E$5:$E$264,F$4) -> 3 | G12: =SUMIFS('Stock by Location'!$G$5:$G$264,'Stock by Location'!$A$5:$A$264,$A12,'Stock by Location'!$E$5:$E$264,G$4) -> 3 | H12: =SUM(C12:G12) -> 22 | I12: =INDEX(Products!$J$5:$J$93,MATCH(A12,Products!$A$5:$A$93,0)) -> 14550 | J12: =H12*I12 -> 320100
A13: BTK-COM-009 | B13: LG Front Load Washer 9 Kg Inverter Steam F4R5VGG2E | C13: =SUMIFS('Stock by Location'!$G$5:$G$264,'Stock by Location'!$A$5:$A$264,$A13,'Stock by Location'!$E$5:$E$264,C$4) -> 10 | D13: =SUMIFS('Stock by Location'!$G$5:$G$264,'Stock by Location'!$A$5:$A$264,$A13,'Stock by Location'!$E$5:$E$264,D$4) -> 6 | E13: =SUMIFS('Stock by Location'!$G$5:$G$264,'Stock by Location'!$A$5:$A$264,$A13,'Stock by Location'!$E$5:$E$264,E$4) -> 5 | F13: =SUMIFS('Stock by Location'!$G$5:$G$264,'Stock by Location'!$A$5:$A$264,$A13,'Stock by Location'!$E$5:$E$264,F$4) -> 3 | G13: =SUMIFS('Stock by Location'!$G$5:$G$264,'Stock by Location'!$A$5:$A$264,$A13,'Stock by Location'!$E$5:$E$264,G$4) -> 4 | H13: =SUM(C13:G13) -> 28 | I13: =INDEX(Products!$J$5:$J$93,MATCH(A13,Products!$A$5:$A$93,0)) -> 24400 | J13: =H13*I13 -> 683200
A14: BTK-COM-010 | B14: Samsung Washing Machine 8 Kg Inverter Steam WW80TA046AX | C14: =SUMIFS('Stock by Location'!$G$5:$G$264,'Stock by Location'!$A$5:$A$264,$A14,'Stock by Location'!$E$5:$E$264,C$4) -> 8 | D14: =SUMIFS('Stock by Location'!$G$5:$G$264,'Stock by Location'!$A$5:$A$264,$A14,'Stock by Location'!$E$5:$E$264,D$4) -> 5 | E14: =SUMIFS('Stock by Location'!$G$5:$G$264,'Stock by Location'!$A$5:$A$264,$A14,'Stock by Location'!$E$5:$E$264,E$4) -> 4 | F14: =SUMIFS('Stock by Location'!$G$5:$G$264,'Stock by Location'!$A$5:$A$264,$A14,'Stock by Location'!$E$5:$E$264,F$4) -> 3 | G14: =SUMIFS('Stock by Location'!$G$5:$G$264,'Stock by Location'!$A$5:$A$264,$A14,'Stock by Location'!$E$5:$E$264,G$4) -> 4 | H14: =SUM(C14:G14) -> 24 | I14: =INDEX(Products!$J$5:$J$93,MATCH(A14,Products!$A$5:$A$93,0)) -> 21600 | J14: =H14*I14 -> 518400
A15: BTK-COM-011 | B15: Zanussi Front Load Washing Machine 7 Kg 1000 RPM ZWF70240S | C15: =SUMIFS('Stock by Location'!$G$5:$G$264,'Stock by Location'!$A$5:$A$264,$A15,'Stock by Location'!$E$5:$E$264,C$4) -> 14 | D15: =SUMIFS('Stock by Location'!$G$5:$G$264,'Stock by Location'!$A$5:$A$264,$A15,'Stock by Location'!$E$5:$E$264,D$4) -> 8 | E15: =SUMIFS('Stock by Location'!$G$5:$G$264,'Stock by Location'!$A$5:$A$264,$A15,'Stock by Location'!$E$5:$E$264,E$4) -> 7 | F15: =SUMIFS('Stock by Location'!$G$5:$G$264,'Stock by Location'!$A$5:$A$264,$A15,'Stock by Location'!$E$5:$E$264,F$4) -> 5 | G15: =SUMIFS('Stock by Location'!$G$5:$G$264,'Stock by Location'!$A$5:$A$264,$A15,'Stock by Location'!$E$5:$E$264,G$4) -> 6 | H15: =SUM(C15:G15) -> 40 | I15: =INDEX(Products!$J$5:$J$93,MATCH(A15,Products!$A$5:$A$93,0)) -> 16800 | J15: =H15*I15 -> 672000
A16: BTK-COM-012 | B16: Toshiba Top Load Washing Machine 10 Kg AEW-E1050SUP | C16: =SUMIFS('Stock by Location'!$G$5:$G$264,'Stock by Location'!$A$5:$A$264,$A16,'Stock by Location'!$E$5:$E$264,C$4) -> 11 | D16: =SUMIFS('Stock by Location'!$G$5:$G$264,'Stock by Location'!$A$5:$A$264,$A16,'Stock by Location'!$E$5:$E$264,D$4) -> 6 | E16: =SUMIFS('Stock by Location'!$G$5:$G$264,'Stock by Location'!$A$5:$A$264,$A16,'Stock by Location'!$E$5:$E$264,E$4) -> 6 | F16: =SUMIFS('Stock by Location'!$G$5:$G$264,'Stock by Location'!$A$5:$A$264,$A16,'Stock by Location'!$E$5:$E$264,F$4) -> 4 | G16: =SUMIFS('Stock by Location'!$G$5:$G$264,'Stock by Location'!$A$5:$A$264,$A16,'Stock by Location'!$E$5:$E$264,G$4) -> 5 | H16: =SUM(C16:G16) -> 32 | I16: =INDEX(Products!$J$5:$J$93,MATCH(A16,Products!$A$5:$A$93,0)) -> 13450 | J16: =H16*I16 -> 430400
... A87: BTK-RM-032 | B87: User Manual & Warranty Card | C87: =SUMIFS('Stock by Location'!$G$5:$G$264,'Stock by Location'!$A$5:$A$264,$A87,'Stock by Location'!$E$5:$E$264,C$4) -> 500 | D87: =SUMIFS('Stock by Location'!$G$5:$G$264,'Stock by Location'!$A$5:$A$264,$A87,'Stock by Location'!$E$5:$E$264,D$4) -> 0 | E87: =SUMIFS('Stock by Location'!$G$5:$G$264,'Stock by Location'!$A$5:$A$264,$A87,'Stock by Location'!$E$5:$E$264,E$4) -> 0 | F87: =SUMIFS('Stock by Location'!$G$5:$G$264,'Stock by Location'!$A$5:$A$264,$A87,'Stock by Location'!$E$5:$E$264,F$4) -> 0 | G87: =SUMIFS('Stock by Location'!$G$5:$G$264,'Stock by Location'!$A$5:$A$264,$A87,'Stock by Location'!$E$5:$E$264,G$4) -> 0 | H87: =SUM(C87:G87) -> 500 | I87: =INDEX(Products!$J$5:$J$93,MATCH(A87,Products!$A$5:$A$93,0)) -> 4 | J87: =H87*I87 -> 2000
A88: Total | C88: =SUM(C5:C87) -> 23784 | D88: =SUM(D5:D87) -> 297 | E88: =SUM(E5:E87) -> 266 | F88: =SUM(F5:F87) -> 179 | G88: =SUM(G5:G87) -> 220 | H88: =SUM(H5:H87) -> 24746 | J88: =SUM(J5:J87) -> 20424776

Sheet Inventory Valuation
A1: Inventory Valuation by Account
A2: Column D = figure used in the Opening Trial Balance (Organization_and_Accounting_Charts.xlsx). Difference must be 0.
A4: Account | B4: Inventory Account | C4: Value per Stock (formula) | D4: Value in Opening TB | E4: Difference
A5: 120100 | B5: Inventory - Refrigerators & Freezers | C5: =SUMIF('Stock by Location'!$D$5:$D$264,A5,'Stock by Location'!$I$5:$I$264) -> 4248100 | D5: 4248100 | E5: =ROUND(C5-D5,2) -> 0
A6: 120200 | B6: Inventory - Washing Machines & Dishwashers | C6: =SUMIF('Stock by Location'!$D$5:$D$264,A6,'Stock by Location'!$I$5:$I$264) -> 3843200 | D6: 3843200 | E6: =ROUND(C6-D6,2) -> 0
A7: 120300 | B7: Inventory - Air Conditioners & Fans | C7: =SUMIF('Stock by Location'!$D$5:$D$264,A7,'Stock by Location'!$I$5:$I$264) -> 3780350 | D7: 3780350 | E7: =ROUND(C7-D7,2) -> 0
A8: 120400 | B8: Inventory - TVs & Audio | C8: =SUMIF('Stock by Location'!$D$5:$D$264,A8,'Stock by Location'!$I$5:$I$264) -> 3248250 | D8: 3248250 | E8: =ROUND(C8-D8,2) -> 0
A9: 120500 | B9: Inventory - Small Kitchen & Home Appliances | C9: =SUMIF('Stock by Location'!$D$5:$D$264,A9,'Stock by Location'!$I$5:$I$264) -> 1394050 | D9: 1394050 | E9: =ROUND(C9-D9,2) -> 0
A10: 120550 | B10: Inventory - Cookers & Ovens | C10: =SUMIF('Stock by Location'!$D$5:$D$264,A10,'Stock by Location'!$I$5:$I$264) -> 1545550 | D10: 1545550 | E10: =ROUND(C10-D10,2) -> 0
A11: 120600 | B11: Inventory - Manufactured Finished Goods | C11: =SUMIF('Stock by Location'!$D$5:$D$264,A11,'Stock by Location'!$I$5:$I$264) -> 926951.5 | D11: 926951.5 | E11: =ROUND(C11-D11,2) -> 0
A12: 120800 | B12: Inventory - Raw Materials & Components | C12: =SUMIF('Stock by Location'!$D$5:$D$264,A12,'Stock by Location'!$I$5:$I$264) -> 1438325 | D12: 1438325 | E12: =ROUND(C12-D12,2) -> 0
A13: Total | C13: =SUM(C5:C12) -> 20424776 | D13: =SUM(D5:D12) -> 20424776 | E13: =SUM(E5:E12) -> 0

Sheet Reordering Rules
A1: Reordering Rules (Min / Max)
A2: When forecast stock falls below Min, Odoo creates an RFQ (Buy) or a Manufacturing Order (Manufacture) up to Max.
A4: Internal Ref | B4: Product | C4: Warehouse | D4: Location | E4: Min Qty | F4: Max Qty | G4: Route | H4: Trigger
A5: BTK-COM-021 | B5: Tornado Stand Fan 16 Inch with Remote Control EFS-36 | C5: Cairo Warehouse (Main) | D5: CAW/Stock | E5: 20 | F5: 60 | G5: Buy | H5: Auto
A6: BTK-COM-022 | B6: Toshiba Ceiling Fan 56 Inch PS-56 | C6: Cairo Warehouse (Main) | D6: CAW/Stock | E6: 25 | F6: 80 | G6: Buy | H6: Auto
A7: BTK-COM-038 | B7: Braun Electric Kettle Stainless Steel 1.7L WK5110 | C7: Cairo Warehouse (Main) | D7: CAW/Stock | E7: 30 | F7: 90 | G7: Buy | H7: Auto
A8: BTK-COM-035 | B8: Moulinex French Blender 450W with Grinder LM242B25 | C8: Cairo Warehouse (Main) | D8: CAW/Stock | E8: 25 | F8: 80 | G8: Buy | H8: Auto
A9: BTK-COM-029 | B9: Samsung Smart TV 55 Inch 4K Crystal UHD CU7000 | C9: Cairo Warehouse (Main) | D9: CAW/Stock | E9: 10 | F9: 40 | G9: Buy | H9: Auto
A10: BTK-COM-017 | B10: Carrier Split AC 1.5 HP Cool/Heat Inverter Optimax | C10: Cairo Warehouse (Main) | D10: CAW/Stock | E10: 10 | F10: 40 | G10: Buy | H10: Auto
A11: BTK-COM-018 | B11: Sharp Split AC 1.5 HP Cool Only Plasmacluster AH-A12YSE | C11: Cairo Warehouse (Main) | D11: CAW/Stock | E11: 12 | F11: 45 | G11: Buy | H11: Auto
A12: BTK-COM-032 | B12: Tornado LED TV 32 Inch HD 32ES9500E | C12: Cairo Warehouse (Main) | D12: CAW/Stock | E12: 20 | F12: 60 | G12: Buy | H12: Auto
A13: BTK-MFG-011 | B13: Beitak Stand Fan 16 Inch with Remote Control | C13: Cairo Warehouse (Main) | D13: CAW/Stock | E13: 20 | F13: 80 | G13: Manufacture | H13: Auto
A14: BTK-MFG-007 | B14: Inverter Remote Fan Control Board | C14: Cairo Warehouse (Main) | D14: CAW/Stock | E14: 40 | F14: 120 | G14: Manufacture | H14: Auto
A15: BTK-MFG-004 | B15: Adjustable TV Wall Mount Bracket 32-65 Inch | C15: Cairo Warehouse (Main) | D15: CAW/Stock | E15: 80 | F15: 250 | G15: Manufacture | H15: Auto
A16: BTK-MFG-006 | B16: Power Distribution Unit & Surge Protector 6-Socket | C16: Cairo Warehouse (Main) | D16: CAW/Stock | E16: 50 | F16: 150 | G16: Manufacture | H16: Auto
... A26: BTK-RM-031 | B26: Screws & Fasteners Kit | C26: Cairo Warehouse (Main) | D26: CAW/Stock | E26: 400 | F26: 1500 | G26: Buy | H26: Auto

Sheet Serial Numbers
A1: Serial Numbers (summary)
A2: 1,546 serial numbers in 23_Serial_Numbers.xlsx - one per appliance unit, used for warranty and returns.
A4: Internal Ref | B4: Product | C4: Serials | D4: Range
A5: BTK-COM-001 | B5: Sharp Refrigerator 18 Cu. Ft. No-Frost Stainless SJ-GV58G-SL | C5: 25 | D5: BTK-COM-001-0001 ... BTK-COM-001-0025
A6: BTK-COM-002 | B6: LG Refrigerator 20 Cu. Ft. Digital Inverter GN-B5722HLHU | C6: 18 | D6: BTK-COM-002-0001 ... BTK-COM-002-0018
A7: BTK-COM-003 | B7: Samsung Refrigerator 22 Cu. Ft. Side-by-Side RS62R5001M9 | C7: 12 | D7: BTK-COM-003-0001 ... BTK-COM-003-0012
A8: BTK-COM-004 | B8: Tornado Refrigerator 14 Cu. Ft. No-Frost RF-48T-SL | C8: 30 | D8: BTK-COM-004-0001 ... BTK-COM-004-0030
A9: BTK-COM-005 | B9: Kiriazi Refrigerator 16 Cu. Ft. Zomoroda No-Frost K330 | C9: 20 | D9: BTK-COM-005-0001 ... BTK-COM-005-0020
A10: BTK-COM-006 | B10: Toshiba Deep Freezer 5 Drawers No-Frost GF-18H-S | C10: 35 | D10: BTK-COM-006-0001 ... BTK-COM-006-0035
A11: BTK-COM-007 | B11: Beko Upright Deep Freezer 7 Drawers RFNE260E13S | C11: 15 | D11: BTK-COM-007-0001 ... BTK-COM-007-0015
A12: BTK-COM-008 | B12: Kiriazi Deep Freezer 4 Drawers E220 | C12: 22 | D12: BTK-COM-008-0001 ... BTK-COM-008-0022
A13: BTK-COM-009 | B13: LG Front Load Washer 9 Kg Inverter Steam F4R5VGG2E | C13: 28 | D13: BTK-COM-009-0001 ... BTK-COM-009-0028
A14: BTK-COM-010 | B14: Samsung Washing Machine 8 Kg Inverter Steam WW80TA046AX | C14: 24 | D14: BTK-COM-010-0001 ... BTK-COM-010-0024
A15: BTK-COM-011 | B15: Zanussi Front Load Washing Machine 7 Kg 1000 RPM ZWF70240S | C15: 40 | D15: BTK-COM-011-0001 ... BTK-COM-011-0040
A16: BTK-COM-012 | B16: Toshiba Top Load Washing Machine 10 Kg AEW-E1050SUP | C16: 32 | D16: BTK-COM-012-0001 ... BTK-COM-012-0032
... A45: BTK-MFG-011 | B45: Beitak Stand Fan 16 Inch with Remote Control | C45: 60 | D45: BTK-MFG-011-0001 ... BTK-MFG-011-0060
A46: Total | C46: =SUM(C5:C45) -> 1546
